Workbook

Sheet Sheet1
A1: Szla | B1: Vevő | C1: Dátum | D1: Kelt_hó | E1: Teljesítés | F1: Telj_hó | G1: Cikk | H1: Termékkör | I1: Termékfajta | J1: Megnevezés | K1: Darab | L1: Beker | M1: SzumBeker | N1: KülföldiÁr | O1: Pénznem | P1: Árfolyam | Q1: Listaár | R1: Elad | S1: SzumElad | T1: Jut_% | U1: Jut | V1: ÜK | W1: Rés | X1: Befolyt | Y1: Column1 | Z1: Befolyt2 | AA1: KÜlföldEUR
A2: 727/2026 | B2: Pro Grip Kft. | C2: 46080 | D2: 2 | E2: 46080 | F2: 2 | G2: 4114/27603 | H2: Rakományrögzítők | I2: Alap | J2: 25/0,4 hn 6,0 m rakományrögzítő kék hozott hevederből | K2: 10 | L2: 262.19 | M2: 2621.9 | N2: 0 | O2: Ft | P2: 0 | Q2: 870 | R2: 970 | S2: 9700 | T2: 13.09 | U2: 1269.73 | V2: Négyesy Gábor | W2: 7078.1 | X2: n | Z2: =IF(Y2<>"",Y2,IF(Table1[[#This Row],[Befolyt]]="i",1,"")) | AA2: =Table1[[#This Row],[KülföldiÁr]]*Table1[[#This Row],[Darab]] -> 0
A3: 727/2026 | B3: Pro Grip Kft. | C3: 46080 | D3: 2 | E3: 46080 | F3: 2 | G3: 4114/27602 | H3: Rakományrögzítők | I3: Alap | J3: 25/0,4 hn 6,0 m rakományrögzítő fekete hozott hevederből | K3: 10 | L3: 262.19 | M3: 2621.9 | N3: 0 | O3: Ft | P3: 0 | Q3: 870 | R3: 970 | S3: 9700 | T3: 13.09 | U3: 1269.73 | V3: Négyesy Gábor | W3: 7078.1 | X3: n | Z3: =IF(Y3<>"",Y3,IF(Table1[[#This Row],[Befolyt]]="i",1,"")) | AA3: =Table1[[#This Row],[KülföldiÁr]]*Table1[[#This Row],[Darab]] -> 0
A4: 727/2026 | B4: Pro Grip Kft. | C4: 46080 | D4: 2 | E4: 46080 | F4: 2 | G4: 4114/27607 | H4: Rakományrögzítők | I4: Alap | J4: 25/0,4 hn 4 m rakományrögzítő kék hozott hevederből | K4: 10 | L4: 262.19 | M4: 2621.9 | N4: 0 | O4: Ft | P4: 0 | Q4: 870 | R4: 970 | S4: 9700 | T4: 13.09 | U4: 1269.73 | V4: Négyesy Gábor | W4: 7078.1 | X4: n | Z4: =IF(Y4<>"",Y4,IF(Table1[[#This Row],[Befolyt]]="i",1,"")) | AA4: =Table1[[#This Row],[KülföldiÁr]]*Table1[[#This Row],[Darab]] -> 0
A5: 727/2026 | B5: Pro Grip Kft. | C5: 46080 | D5: 2 | E5: 46080 | F5: 2 | G5: 4114/27606 | H5: Rakományrögzítők | I5: Alap | J5: 25/0,4 hn 4 m rakományrögzítő fekete hozott hevederből | K5: 10 | L5: 262.19 | M5: 2621.9 | N5: 0 | O5: Ft | P5: 0 | Q5: 870 | R5: 970 | S5: 9700 | T5: 13.09 | U5: 1269.73 | V5: Négyesy Gábor | W5: 7078.1 | X5: n | Z5: =IF(Y5<>"",Y5,IF(Table1[[#This Row],[Befolyt]]="i",1,"")) | AA5: =Table1[[#This Row],[KülföldiÁr]]*Table1[[#This Row],[Darab]] -> 0
A6: 727/2026 | B6: Pro Grip Kft. | C6: 46080 | D6: 2 | E6: 46080 | F6: 2 | G6: 4114/27611 | H6: Rakományrögzítők | I6: Alap | J6: 25/0,4 hn 3,0 m rakományrögzítő kék hozott hevederből | K6: 9 | L6: 262.19 | M6: 2359.71 | N6: 0 | O6: Ft | P6: 0 | Q6: 870 | R6: 970 | S6: 8730 | T6: 13.09 | U6: 1142.757 | V6: Négyesy Gábor | W6: 6370.29 | X6: n | Z6: =IF(Y6<>"",Y6,IF(Table1[[#This Row],[Befolyt]]="i",1,"")) | AA6: =Table1[[#This Row],[KülföldiÁr]]*Table1[[#This Row],[Darab]] -> 0
A7: 727/2026 | B7: Pro Grip Kft. | C7: 46080 | D7: 2 | E7: 46080 | F7: 2 | G7: 4114/27612 | H7: Rakományrögzítők | I7: Alap | J7: 25/0,4 hn 3,0 m rakományrögzítő kék | K7: 1 | L7: 379.98 | M7: 379.98 | N7: 0 | O7: Ft | P7: 0 | Q7: 1160 | R7: 1260 | S7: 1260 | T7: 12.38 | U7: 155.988 | V7: Négyesy Gábor | W7: 880.02 | X7: n | Z7: =IF(Y7<>"",Y7,IF(Table1[[#This Row],[Befolyt]]="i",1,"")) | AA7: =Table1[[#This Row],[KülföldiÁr]]*Table1[[#This Row],[Darab]] -> 0
A8: 727/2026 | B8: Pro Grip Kft. | C8: 46080 | D8: 2 | E8: 46080 | F8: 2 | G8: 4114/27610 | H8: Rakományrögzítők | I8: Alap | J8: 25/0,4 hn 3,0 m rakományrögzítő fekete hozott hevederből | K8: 10 | L8: 262.19 | M8: 2621.9 | N8: 0 | O8: Ft | P8: 0 | Q8: 870 | R8: 970 | S8: 9700 | T8: 13.09 | U8: 1269.73 | V8: Négyesy Gábor | W8: 7078.1 | X8: n | Z8: =IF(Y8<>"",Y8,IF(Table1[[#This Row],[Befolyt]]="i",1,"")) | AA8: =Table1[[#This Row],[KülföldiÁr]]*Table1[[#This Row],[Darab]] -> 0
A9: 727/2026 | B9: Pro Grip Kft. | C9: 46080 | D9: 2 | E9: 46080 | F9: 2 | G9: 4114/27617 | H9: Rakományrögzítők | I9: Alap | J9: 25/0,4 hn 2 m rakományrögzítő kék hozott hevederből | K9: 3 | L9: 262.19 | M9: 786.57 | N9: 0 | O9: Ft | P9: 0 | Q9: 870 | R9: 970 | S9: 2910 | T9: 13.09 | U9: 380.919 | V9: Négyesy Gábor | W9: 2123.43 | X9: n | Z9: =IF(Y9<>"",Y9,IF(Table1[[#This Row],[Befolyt]]="i",1,"")) | AA9: =Table1[[#This Row],[KülföldiÁr]]*Table1[[#This Row],[Darab]] -> 0
A10: 727/2026 | B10: Pro Grip Kft. | C10: 46080 | D10: 2 | E10: 46080 | F10: 2 | G10: 4114/27618 | H10: Rakományrögzítők | I10: Alap | J10: 25/0,4 hn 2 m rakományrögzítő kék | K10: 7 | L10: 341.98 | M10: 2393.86 | N10: 0 | O10: Ft | P10: 0 | Q10: 1060 | R10: 1160 | S10: 8120 | T10: 12.59 | U10: 1022.308 | V10: Négyesy Gábor | W10: 5726.14 | X10: n | Z10: =IF(Y10<>"",Y10,IF(Table1[[#This Row],[Befolyt]]="i",1,"")) | AA10: =Table1[[#This Row],[KülföldiÁr]]*Table1[[#This Row],[Darab]] -> 0
A11: 727/2026 | B11: Pro Grip Kft. | C11: 46080 | D11: 2 | E11: 46080 | F11: 2 | G11: 4114/27616 | H11: Rakományrögzítők | I11: Alap | J11: 25/0,4 hn 2 m rakományrögzítő fekete hozott hevederből | K11: 10 | L11: 262.19 | M11: 2621.9 | N11: 0 | O11: Ft | P11: 0 | Q11: 870 | R11: 970 | S11: 9700 | T11: 13.09 | U11: 1269.73 | V11: Négyesy Gábor | W11: 7078.1 | X11: n | Z11: =IF(Y11<>"",Y11,IF(Table1[[#This Row],[Befolyt]]="i",1,"")) | AA11: =Table1[[#This Row],[KülföldiÁr]]*Table1[[#This Row],[Darab]] -> 0
A12: 727/2026 | B12: Pro Grip Kft. | C12: 46080 | D12: 2 | E12: 46080 | F12: 2 | G12: 4114/27622 | H12: Rakományrögzítők | I12: Alap | J12: 25/0,4 hn 1,0 m rakományrögzítő kék hozott hevederből | K12: 1 | L12: 262.19 | M12: 262.19 | N12: 0 | O12: Ft | P12: 0 | Q12: 870 | R12: 970 | S12: 970 | T12: 13.09 | U12: 126.973 | V12: Négyesy Gábor | W12: 707.81 | X12: n | Z12: =IF(Y12<>"",Y12,IF(Table1[[#This Row],[Befolyt]]="i",1,"")) | AA12: =Table1[[#This Row],[KülföldiÁr]]*Table1[[#This Row],[Darab]] -> 0
A13: 727/2026 | B13: Pro Grip Kft. | C13: 46080 | D13: 2 | E13: 46080 | F13: 2 | G13: 4114/27621 | H13: Rakományrögzítők | I13: Alap | J13: 25/0,4 hn 1,0 m rakományrögzítő kék | K13: 9 | L13: 303.99 | M13: 2735.91 | N13: 0 | O13: Ft | P13: 0 | Q13: 970 | R13: 1070 | S13: 9630 | T13: 12.8 | U13: 1232.64 | V13: Négyesy Gábor | W13: 6894.09 | X13: n | Z13: =IF(Y13<>"",Y13,IF(Table1[[#This Row],[Befolyt]]="i",1,"")) | AA13: =Table1[[#This Row],[KülföldiÁr]]*Table1[[#This Row],[Darab]] -> 0
... A111: 707/2026 | B111: Hankook Tire Magyarország Kft. | C111: 46080 | D111: 2 | E111: 46080 | F111: 2 | G111: 143/16946 | H111: Emelőgép szolgáltatások | I111: Egyéb | J111: GLS Fuvar | K111: 1 | L111: 2723 | M111: 2723 | N111: 0 | O111: EUR | P111: 375.74 | Q111: 2723 | R111: 0 | S111: 0 | T111: 0 | U111: 0 | V111: Molnár Ferenc | W111: -2723 | X111: n | Z111: =IF(Y111<>"",Y111,IF(Table1[[#This Row],[Befolyt]]="i",1,"")) | AA111: =Table1[[#This Row],[KülföldiÁr]]*Table1[[#This Row],[Darab]] -> 0
A112: 707/2026 | B112: Hankook Tire Magyarország Kft. | C112: 46080 | D112: 2 | E112: 46080 | F112: 2 | G112: 12531/27263 | H112: Emelőberendezések | I112: Beruházás | J112: 620103 Noise & dust filter VM60-270 4201567 | K112: 1 | L112: 5026.6 | M112: 5026.6 | N112: 25 | O112: EUR | P112: 375.74 | Q112: 9840 | R112: 9393.5 | S112: 9393.5 | T112: 3.75 | U112: =Table1[[#This Row],[Jut_%]]*Table1[[#This Row],[SzumElad]]/100 -> 352.25625 | V112: Molnár Ferenc | W112: 4366.9 | X112: n | Z112: =IF(Y112<>"",Y112,IF(Table1[[#This Row],[Befolyt]]="i",1,"")) | AA112: =Table1[[#This Row],[KülföldiÁr]]*Table1[[#This Row],[Darab]] -> 25
A113: 707/2026 | B113: Hankook Tire Magyarország Kft. | C113: 46080 | D113: 2 | E113: 46080 | F113: 2 | G113: 12531/27191 | H113: Emelőberendezések | I113: Beruházás | J113: 620010LS Swivel bend, low built 4202298 | K113: 2 | L113: 82705.78 | M113: 165411.56 | N113: 405 | O113: EUR | P113: 375.74 | Q113: 162000 | R113: 152174.7 | S113: 304349.4 | T113: 3.75 | U113: =Table1[[#This Row],[Jut_%]]*Table1[[#This Row],[SzumElad]]/100 -> 11413.103 | V113: Molnár Ferenc | W113: 138937.84 | X113: n | Z113: =IF(Y113<>"",Y113,IF(Table1[[#This Row],[Befolyt]]="i",1,"")) | AA113: =Table1[[#This Row],[KülföldiÁr]]*Table1[[#This Row],[Darab]] -> 810
A114: 707/2026 | B114: Hankook Tire Magyarország Kft. | C114: 46080 | D114: 2 | E114: 46080 | F114: 2 | G114: 12531/27192 | H114: Emelőberendezések | I114: Beruházás | J114: 610941 Rubber sleeve, lower 110x515mm 4201493 | K114: 4 | L114: 10163.14 | M114: 40652.56 | N114: 50 | O114: EUR | P114: 375.74 | Q114: 17900 | R114: 18787 | S114: 75148 | T114: 3.75 | U114: =Table1[[#This Row],[Jut_%]]*Table1[[#This Row],[SzumElad]]/100 -> 2818.05 | V114: Molnár Ferenc | W114: 34495.44 | X114: n | Z114: =IF(Y114<>"",Y114,IF(Table1[[#This Row],[Befolyt]]="i",1,"")) | AA114: =Table1[[#This Row],[KülföldiÁr]]*Table1[[#This Row],[Darab]] -> 200
A115: 707/2026 | B115: Hankook Tire Magyarország Kft. | C115: 46080 | D115: 2 | E115: 46080 | F115: 2 | G115: 12531/23534 | H115: Emelőberendezések | I115: Beruházás | J115: 610933 Légszürő filter betét 610931 szűrőhöz, filter insert 4201492 | K115: 4 | L115: 25565.14 | M115: 102260.56 | N115: 125 | O115: EUR | P115: 375.74 | Q115: 80750 | R115: 46967.5 | S115: 187870 | T115: 3.75 | U115: =Table1[[#This Row],[Jut_%]]*Table1[[#This Row],[SzumElad]]/100 -> 7045.125 | V115: Molnár Ferenc | W115: 85609.44 | X115: n | Z115: =IF(Y115<>"",Y115,IF(Table1[[#This Row],[Befolyt]]="i",1,"")) | AA115: =Table1[[#This Row],[KülföldiÁr]]*Table1[[#This Row],[Darab]] -> 500
A116: 707/2026 | B116: Hankook Tire Magyarország Kft. | C116: 46080 | D116: 2 | E116: 46080 | F116: 2 | G116: 12531/23390 | H116: Emelőberendezések | I116: Beruházás | J116: 610865 Gumi tömítés (gasket) OD: 235mm, ID 110mm gumibálamegfogóhoz 4201475 | K116: 1 | L116: 34708.38 | M116: 34708.38 | N116: 150 | O116: EUR | P116: 375.74 | Q116: 75900 | R116: 56361 | S116: 56361 | T116: 3.75 | U116: =Table1[[#This Row],[Jut_%]]*Table1[[#This Row],[SzumElad]]/100 -> 2113.5375 | V116: Molnár Ferenc | W116: 21652.62 | X116: n | Z116: =IF(Y116<>"",Y116,IF(Table1[[#This Row],[Befolyt]]="i",1,"")) | AA116: =Table1[[#This Row],[KülföldiÁr]]*Table1[[#This Row],[Darab]] -> 150
A117: 707/2026 | B117: Hankook Tire Magyarország Kft. | C117: 46080 | D117: 2 | E117: 46080 | F117: 2 | G117: 12531/27916 | H117: Emelőberendezések | I117: Beruházás | J117: 4309682 Szűrő, Filter Unit Cpl Black, 51-38mm 610931 | K117: 1 | L117: 99265.88 | M117: 99265.88 | N117: 495 | O117: EUR | P117: 375.74 | Q117: 198100 | R117: 185991.3 | S117: 185991.3 | T117: 3.75 | U117: =Table1[[#This Row],[Jut_%]]*Table1[[#This Row],[SzumElad]]/100 -> 6974.6737 | V117: Molnár Ferenc | W117: 86725.42 | X117: n | Z117: =IF(Y117<>"",Y117,IF(Table1[[#This Row],[Befolyt]]="i",1,"")) | AA117: =Table1[[#This Row],[KülföldiÁr]]*Table1[[#This Row],[Darab]] -> 495
A118: 706/2026 | B118: Gutman Lifting s.r.o. | C118: 46080 | D118: 2 | E118: 46083 | F118: 3 | G118: 259/2079 | H118: Megfogók | I118: Alap | J118: HCF15ahs automata daruvilla 1500 kg | K118: 1 | L118: 167645.73 | M118: 167645.73 | N118: 621.88 | O118: EUR | P118: 379.18 | Q118: 395150 | R118: 235804.45 | S118: 235804.45 | T118: 0 | U118: 0 | V118: Buzás Péter | W118: 68158.72 | X118: n | Z118: =IF(Y118<>"",Y118,IF(Table1[[#This Row],[Befolyt]]="i",1,"")) | AA118: =Table1[[#This Row],[KülföldiÁr]]*Table1[[#This Row],[Darab]] -> 621.88
A119: 706/2026 | B119: Gutman Lifting s.r.o. | C119: 46080 | D119: 2 | E119: 46083 | F119: 3 | G119: 2102/1022 | H119: Fuvar | I119: Egyéb | J119: Csomagolási díj | K119: 1 | L119: 1900 | M119: 1900 | N119: 6 | O119: EUR | P119: 379.18 | Q119: 3500 | R119: 2275.08 | S119: 2275.08 | T119: 0 | U119: 0 | V119: Buzás Péter | W119: 375.08 | X119: n | Z119: =IF(Y119<>"",Y119,IF(Table1[[#This Row],[Befolyt]]="i",1,"")) | AA119: =Table1[[#This Row],[KülföldiÁr]]*Table1[[#This Row],[Darab]] -> 6
A120: 706/2026 | B120: Gutman Lifting s.r.o. | C120: 46080 | D120: 2 | E120: 46083 | F120: 3 | G120: 2102/15560 | H120: Fuvar | I120: Egyéb | J120: *P. 7 Fuvar | K120: 1 | L120: 17659.78 | M120: 17659.78 | N120: 47 | O120: EUR | P120: 379.18 | Q120: 47 | R120: 17821.46 | S120: 17821.46 | T120: 0 | U120: 0 | V120: Buzás Péter | W120: 161.68 | X120: n | Z120: =IF(Y120<>"",Y120,IF(Table1[[#This Row],[Befolyt]]="i",1,"")) | AA120: =Table1[[#This Row],[KülföldiÁr]]*Table1[[#This Row],[Darab]] -> 47
A121: 705/2026 | B121: Kamionvilág Kft | C121: 46080 | D121: 2 | E121: 46080 | F121: 2 | G121: 4114/969 | H121: Rakományrögzítők | I121: Alap | J121: 50/2 hh 6 m rakományrögzítő 11076 | K121: 20 | L121: 1601.36 | M121: 32027.2 | N121: 0 | O121: Ft | P121: 0 | Q121: 5330 | R121: 3838 | S121: 76760 | T121: 1.99 | U121: 1527.524 | V121: Négyesy Gábor | W121: 44732.8 | X121: n | Z121: =IF(Y121<>"",Y121,IF(Table1[[#This Row],[Befolyt]]="i",1,"")) | AA121: =Table1[[#This Row],[KülföldiÁr]]*Table1[[#This Row],[Darab]] -> 0
A122: 705/2026 | B122: Kamionvilág Kft | C122: 46080 | D122: 2 | E122: 46080 | F122: 2 | G122: 4114/259 | H122: Rakományrögzítők | I122: Alap | J122: 50/2 hh 4,0 m rakományrögzítő 11075 | K122: 20 | L122: 1385.66 | M122: 27713.2 | N122: 0 | O122: Ft | P122: 0 | Q122: 4010 | R122: 3543 | S122: 70860 | T122: 6.67 | U122: 4726.362 | V122: Négyesy Gábor | W122: 43146.8 | X122: n | Z122: =IF(Y122<>"",Y122,IF(Table1[[#This Row],[Befolyt]]="i",1,"")) | AA122: =Table1[[#This Row],[KülföldiÁr]]*Table1[[#This Row],[Darab]] -> 0
A123: 705/2026 | B123: Kamionvilág Kft | C123: 46080 | D123: 2 | E123: 46080 | F123: 2 | G123: 4111/236 | H123: Rakományrögzítők | I123: Alap | J123: 35/1 hh 6,0 m rakományrögzítő 11074 | K123: 40 | L123: 776.81 | M123: 31072.4 | N123: 0 | O123: Ft | P123: 0 | Q123: 2000 | R123: 1515 | S123: 60600 | T123: 3.06 | U123: 1854.36 | V123: Négyesy Gábor | W123: 29527.6 | X123: n | Z123: =IF(Y123<>"",Y123,IF(Table1[[#This Row],[Befolyt]]="i",1,"")) | AA123: =Table1[[#This Row],[KülföldiÁr]]*Table1[[#This Row],[Darab]] -> 0
A124: 704/2026 | B124: Vasex Kft. | C124: 46080 | D124: 2 | E124: 46080 | F124: 2 | G124: 21111/4 | H124: Textilkötelek hevederek | I124: Alap | J124: irs 10 2,0/4 m körkötél | K124: 3 | L124: 588.56 | M124: 1765.68 | N124: 0 | O124: Ft | P124: 0 | Q124: 2700 | R124: 1800 | S124: 5400 | T124: 3 | U124: 162 | V124: Halász Miklós | W124: 3634.32 | X124: n | Z124: =IF(Y124<>"",Y124,IF(Table1[[#This Row],[Befolyt]]="i",1,"")) | AA124: =Table1[[#This Row],[KülföldiÁr]]*Table1[[#This Row],[Darab]] -> 0
A125: 704/2026 | B125: Vasex Kft. | C125: 46080 | D125: 2 | E125: 46080 | F125: 2 | G125: 2102/1022 | H125: Fuvar | I125: Egyéb | J125: Csomagolási díj | K125: 1 | L125: 1900 | M125: 1900 | N125: 0 | O125: Ft | P125: 0 | Q125: 3500 | R125: 0 | S125: 0 | T125: 0 | U125: 0 | V125: Halász Miklós | W125: -1900 | X125: n | Z125: =IF(Y125<>"",Y125,IF(Table1[[#This Row],[Befolyt]]="i",1,"")) | AA125: =Table1[[#This Row],[KülföldiÁr]]*Table1[[#This Row],[Darab]] -> 0
A126: 704/2026 | B126: Vasex Kft. | C126: 46080 | D126: 2 | E126: 46080 | F126: 2 | G126: 4111/257 | H126: Rakományrögzítők | I126: Alap | J126: 50/2 hh 12 m rakományrögzítő 11078 | K126: 3 | L126: 1738.05 | M126: 5214.15 | N126: 0 | O126: Ft | P126: 0 | Q126: 5100 | R126: 5750 | S126: 17250 | T126: 3 | U126: 517.5 | V126: Halász Miklós | W126: 12035.85 | X126: n | Z126: =IF(Y126<>"",Y126,IF(Table1[[#This Row],[Befolyt]]="i",1,"")) | AA126: =Table1[[#This Row],[KülföldiÁr]]*Table1[[#This Row],[Darab]] -> 0
A127: 704/2026 | B127: Vasex Kft. | C127: 46080 | D127: 2 | E127: 46080 | F127: 2 | G127: 4111/256 | H127: Rakományrögzítők | I127: Alap | J127: 50/2 hh 10 m rakományrögzítő 11077 | K127: 3 | L127: 2165.51 | M127: 6496.53 | N127: 0 | O127: Ft | P127: 0 | Q127: 4800 | R127: 5565 | S127: 16695 | T127: 3 | U127: 500.85 | V127: Halász Miklós | W127: 10198.47 | X127: n | Z127: =IF(Y127<>"",Y127,IF(Table1[[#This Row],[Befolyt]]="i",1,"")) | AA127: =Table1[[#This Row],[KülföldiÁr]]*Table1[[#This Row],[Darab]] -> 0
A128: 704/2026 | B128: Vasex Kft. | C128: 46080 | D128: 2 | E128: 46080 | F128: 2 | G128: 4111/236 | H128: Rakományrögzítők | I128: Alap | J128: 35/1 hh 6,0 m rakományrögzítő 11074 | K128: 10 | L128: 776.81 | M128: 7768.1 | N128: 0 | O128: Ft | P128: 0 | Q128: 2000 | R128: 1515 | S128: 15150 | T128: 2.5 | U128: 378.75 | V128: Halász Miklós | W128: 7381.9 | X128: n | Z128: =IF(Y128<>"",Y128,IF(Table1[[#This Row],[Befolyt]]="i",1,"")) | AA128: =Table1[[#This Row],[KülföldiÁr]]*Table1[[#This Row],[Darab]] -> 0
A129: 704/2026 | B129: Vasex Kft. | C129: 46080 | D129: 2 | E129: 46080 | F129: 2 | G129: 2416/15389 | H129: Kapcsolóelemek | I129: Alap | J129: 3,25 PSO sekli EN13889 | K129: 2 | L129: 709.76 | M129: 1419.52 | N129: 0 | O129: Ft | P129: 0 | Q129: 1950 | R129: 1380 | S129: 2760 | T129: 0.17 | U129: 4.692 | V129: Halász Miklós | W129: 1340.48 | X129: n | Z129: =IF(Y129<>"",Y129,IF(Table1[[#This Row],[Befolyt]]="i",1,"")) | AA129: =Table1[[#This Row],[KülföldiÁr]]*Table1[[#This Row],[Darab]] -> 0
... A176: 689/2026 | B176: Bau-Trans Kft. | C176: 46079 | D176: 2 | E176: 46065 | F176: 2 | G176: 2317/752 | H176: Lánc függesztékek | I176: Alap | J176: RLSP 13-8 biztosító csap | K176: 2 | L176: 184.7 | M176: 369.4 | N176: 0 | O176: Ft | P176: 0 | Q176: 1150 | R176: 1035 | S176: 2070 | T176: 2.5 | U176: 51.75 | V176: Négyesy Gábor | W176: 1700.6 | X176: n | Z176: =IF(Y176<>"",Y176,IF(Table1[[#This Row],[Befolyt]]="i",1,"")) | AA176: =Table1[[#This Row],[KülföldiÁr]]*Table1[[#This Row],[Darab]] -> 0
A177: 689/2026 | B177: Bau-Trans Kft. | C177: 46079 | D177: 2 | E177: 46065 | F177: 2 | G177: 2327/10191 | H177: Lánc függesztékek | I177: Alap | J177: PSG 10 RLS bizt.csap | K177: 3 | L177: 953.29 | M177: 2859.87 | N177: 0 | O177: Ft | P177: 0 | Q177: 1110 | R177: 1050 | S177: 3150 | T177: 3.65 | U177: =Table1[[#This Row],[Jut_%]]*Table1[[#This Row],[SzumElad]]/100 -> 114.975 | V177: Négyesy Gábor | W177: 290.13 | X177: n | Z177: =IF(Y177<>"",Y177,IF(Table1[[#This Row],[Befolyt]]="i",1,"")) | AA177: =Table1[[#This Row],[KülföldiÁr]]*Table1[[#This Row],[Darab]] -> 0
A178: 689/2026 | B178: Bau-Trans Kft. | C178: 46079 | D178: 2 | E178: 46065 | F178: 2 | G178: 2104/982 | H178: Saját munka | I178: Egyéb | J178: Javítási rezsi óradíj | K178: 1 | L178: 7195.04 | M178: 7195.04 | N178: 0 | O178: Ft | P178: 0 | Q178: 12000 | R178: 12000 | S178: 12000 | T178: 0 | U178: 0 | V178: Négyesy Gábor | W178: 4804.96 | X178: n | Z178: =IF(Y178<>"",Y178,IF(Table1[[#This Row],[Befolyt]]="i",1,"")) | AA178: =Table1[[#This Row],[KülföldiÁr]]*Table1[[#This Row],[Darab]] -> 0
A179: 689/2026 | B179: Bau-Trans Kft. | C179: 46079 | D179: 2 | E179: 46065 | F179: 2 | G179: 2317/25172 | H179: Lánc függesztékek | I179: Alap | J179: Alutábla RLS 10 | K179: 23 | L179: 164.3 | M179: 3778.9 | N179: 0 | O179: Ft | P179: 0 | Q179: 960 | R179: 864 | S179: 19872 | T179: 2.5 | U179: 496.8 | V179: Négyesy Gábor | W179: 16093.1 | X179: n | Z179: =IF(Y179<>"",Y179,IF(Table1[[#This Row],[Befolyt]]="i",1,"")) | AA179: =Table1[[#This Row],[KülföldiÁr]]*Table1[[#This Row],[Darab]] -> 0
A180: 689/2026 | B180: Bau-Trans Kft. | C180: 46079 | D180: 2 | E180: 46065 | F180: 2 | G180: 2317/631 | H180: Lánc függesztékek | I180: Alap | J180: 10 biztosító lemez /4mm csavarral/ | K180: 8 | L180: 185.02 | M180: 1480.16 | N180: 0 | O180: Ft | P180: 0 | Q180: 1018 | R180: 1233 | S180: 9864 | T180: 11.1 | U180: 1094.904 | V180: Négyesy Gábor | W180: 8383.84 | X180: n | Z180: =IF(Y180<>"",Y180,IF(Table1[[#This Row],[Befolyt]]="i",1,"")) | AA180: =Table1[[#This Row],[KülföldiÁr]]*Table1[[#This Row],[Darab]] -> 0
A181: 688/2026 | B181: TRGY Tokodaltárói Rácsgyártó K. Kft. | C181: 46079 | D181: 2 | E181: 46076 | F181: 2 | G181: 21214/115 | H181: Textilkötelek hevederek | I181: Alap | J181: id 400 5,0 m füles heveder A05228-A05229 | K181: 2 | L181: 3519.28 | M181: 7038.56 | N181: 0 | O181: Ft | P181: 0 | Q181: 13000 | R181: 18280 | S181: 36560 | T181: 18.67 | U181: 6825.752 | V181: Négyesy Gábor | W181: 29521.44 | X181: n | Z181: =IF(Y181<>"",Y181,IF(Table1[[#This Row],[Befolyt]]="i",1,"")) | AA181: =Table1[[#This Row],[KülföldiÁr]]*Table1[[#This Row],[Darab]] -> 0
A182: 688/2026 | B182: TRGY Tokodaltárói Rácsgyártó K. Kft. | C182: 46079 | D182: 2 | E182: 46076 | F182: 2 | G182: 2102/8427 | H182: Fuvar | I182: Egyéb | J182: *CS.10 Fuvar | K182: 1 | L182: 2600 | M182: 2600 | N182: 0 | O182: Ft | P182: 0 | Q182: 2600 | R182: 3000 | S182: 3000 | T182: 0 | U182: 0 | V182: Négyesy Gábor | W182: 400 | X182: n | Z182: =IF(Y182<>"",Y182,IF(Table1[[#This Row],[Befolyt]]="i",1,"")) | AA182: =Table1[[#This Row],[KülföldiÁr]]*Table1[[#This Row],[Darab]] -> 0
A183: 687/2026 | B183: FémAlk Zrt. | C183: 46079 | D183: 2 | E183: 46079 | F183: 2 | G183: 23164/20616 | H183: Lánc függesztékek | I183: Alap | J183: lrg 4 - 236 KRHG - lánc függeszték 1 m EP 26168 | K183: 1 | L183: 10698.63 | M183: 10698.63 | N183: 0 | O183: Ft | P183: 0 | Q183: 30500 | R183: 33000 | S183: 33000 | T183: 12.27 | U183: 4049.1 | V183: Négyesy Gábor | W183: 22301.37 | X183: n | Z183: =IF(Y183<>"",Y183,IF(Table1[[#This Row],[Befolyt]]="i",1,"")) | AA183: =Table1[[#This Row],[KülföldiÁr]]*Table1[[#This Row],[Darab]] -> 0
...

Sheet ÜK_ELSZÁM
A1: Befolyt | B1: ÜK | C1: Szlasz. | D1: HÓ | E1: Vnév | F1: TKÖRÖK | G1: FIZET | H1: JUT_% | I1: JUT | J1: JUT_fiz
A2: =Table1[[#This Row],[Befolyt]] -> n | B2: =Table1[[#This Row],[ÜK]] -> Négyesy Gábor | C2: =Table1[[#This Row],[Szla]] -> 727/2026 | D2: =Table1[[#This Row],[Kelt_hó]] -> 2 | E2: =Table1[[#This Row],[Vevő]] -> Pro Grip Kft. | F2: =Table1[[#This Row],[Termékkör]] -> Rakományrögzítők | G2: =Table1[[#This Row],[SzumElad]] -> 9700 | H2: =Table1[[#This Row],[Jut_%]] -> 13.09 | I2: =Table1[[#This Row],[Jut]] -> 1269.73 | J2: =Table1[[#This Row],[Column1]] -> 0
A3: =Table1[[#This Row],[Befolyt]] -> n | B3: =Table1[[#This Row],[ÜK]] -> Négyesy Gábor | C3: =Table1[[#This Row],[Szla]] -> 727/2026 | D3: =Table1[[#This Row],[Kelt_hó]] -> 2 | E3: =Table1[[#This Row],[Vevő]] -> Pro Grip Kft. | F3: =Table1[[#This Row],[Termékkör]] -> Rakományrögzítők | G3: =Table1[[#This Row],[SzumElad]] -> 9700 | H3: =Table1[[#This Row],[Jut_%]] -> 13.09 | I3: =Table1[[#This Row],[Jut]] -> 1269.73 | J3: =Table1[[#This Row],[Column1]] -> 0
A4: =Table1[[#This Row],[Befolyt]] -> n | B4: =Table1[[#This Row],[ÜK]] -> Négyesy Gábor | C4: =Table1[[#This Row],[Szla]] -> 727/2026 | D4: =Table1[[#This Row],[Kelt_hó]] -> 2 | E4: =Table1[[#This Row],[Vevő]] -> Pro Grip Kft. | F4: =Table1[[#This Row],[Termékkör]] -> Rakományrögzítők | G4: =Table1[[#This Row],[SzumElad]] -> 9700 | H4: =Table1[[#This Row],[Jut_%]] -> 13.09 | I4: =Table1[[#This Row],[Jut]] -> 1269.73 | J4: =Table1[[#This Row],[Column1]] -> 0
A5: =Table1[[#This Row],[Befolyt]] -> n | B5: =Table1[[#This Row],[ÜK]] -> Négyesy Gábor | C5: =Table1[[#This Row],[Szla]] -> 727/2026 | D5: =Table1[[#This Row],[Kelt_hó]] -> 2 | E5: =Table1[[#This Row],[Vevő]] -> Pro Grip Kft. | F5: =Table1[[#This Row],[Termékkör]] -> Rakományrögzítők | G5: =Table1[[#This Row],[SzumElad]] -> 9700 | H5: =Table1[[#This Row],[Jut_%]] -> 13.09 | I5: =Table1[[#This Row],[Jut]] -> 1269.73 | J5: =Table1[[#This Row],[Column1]] -> 0
A6: =Table1[[#This Row],[Befolyt]] -> n | B6: =Table1[[#This Row],[ÜK]] -> Négyesy Gábor | C6: =Table1[[#This Row],[Szla]] -> 727/2026 | D6: =Table1[[#This Row],[Kelt_hó]] -> 2 | E6: =Table1[[#This Row],[Vevő]] -> Pro Grip Kft. | F6: =Table1[[#This Row],[Termékkör]] -> Rakományrögzítők | G6: =Table1[[#This Row],[SzumElad]] -> 8730 | H6: =Table1[[#This Row],[Jut_%]] -> 13.09 | I6: =Table1[[#This Row],[Jut]] -> 1142.757 | J6: =Table1[[#This Row],[Column1]] -> 0
A7: =Table1[[#This Row],[Befolyt]] -> n | B7: =Table1[[#This Row],[ÜK]] -> Négyesy Gábor | C7: =Table1[[#This Row],[Szla]] -> 727/2026 | D7: =Table1[[#This Row],[Kelt_hó]] -> 2 | E7: =Table1[[#This Row],[Vevő]] -> Pro Grip Kft. | F7: =Table1[[#This Row],[Termékkör]] -> Rakományrögzítők | G7: =Table1[[#This Row],[SzumElad]] -> 1260 | H7: =Table1[[#This Row],[Jut_%]] -> 12.38 | I7: =Table1[[#This Row],[Jut]] -> 155.988 | J7: =Table1[[#This Row],[Column1]] -> 0
A8: =Table1[[#This Row],[Befolyt]] -> n | B8: =Table1[[#This Row],[ÜK]] -> Négyesy Gábor | C8: =Table1[[#This Row],[Szla]] -> 727/2026 | D8: =Table1[[#This Row],[Kelt_hó]] -> 2 | E8: =Table1[[#This Row],[Vevő]] -> Pro Grip Kft. | F8: =Table1[[#This Row],[Termékkör]] -> Rakományrögzítők | G8: =Table1[[#This Row],[SzumElad]] -> 9700 | H8: =Table1[[#This Row],[Jut_%]] -> 13.09 | I8: =Table1[[#This Row],[Jut]] -> 1269.73 | J8: =Table1[[#This Row],[Column1]] -> 0
A9: =Table1[[#This Row],[Befolyt]] -> n | B9: =Table1[[#This Row],[ÜK]] -> Négyesy Gábor | C9: =Table1[[#This Row],[Szla]] -> 727/2026 | D9: =Table1[[#This Row],[Kelt_hó]] -> 2 | E9: =Table1[[#This Row],[Vevő]] -> Pro Grip Kft. | F9: =Table1[[#This Row],[Termékkör]] -> Rakományrögzítők | G9: =Table1[[#This Row],[SzumElad]] -> 2910 | H9: =Table1[[#This Row],[Jut_%]] -> 13.09 | I9: =Table1[[#This Row],[Jut]] -> 380.919 | J9: =Table1[[#This Row],[Column1]] -> 0
A10: =Table1[[#This Row],[Befolyt]] -> n | B10: =Table1[[#This Row],[ÜK]] -> Négyesy Gábor | C10: =Table1[[#This Row],[Szla]] -> 727/2026 | D10: =Table1[[#This Row],[Kelt_hó]] -> 2 | E10: =Table1[[#This Row],[Vevő]] -> Pro Grip Kft. | F10: =Table1[[#This Row],[Termékkör]] -> Rakományrögzítők | G10: =Table1[[#This Row],[SzumElad]] -> 8120 | H10: =Table1[[#This Row],[Jut_%]] -> 12.59 | I10: =Table1[[#This Row],[Jut]] -> 1022.308 | J10: =Table1[[#This Row],[Column1]] -> 0
A11: =Table1[[#This Row],[Befolyt]] -> n | B11: =Table1[[#This Row],[ÜK]] -> Négyesy Gábor | C11: =Table1[[#This Row],[Szla]] -> 727/2026 | D11: =Table1[[#This Row],[Kelt_hó]] -> 2 | E11: =Table1[[#This Row],[Vevő]] -> Pro Grip Kft. | F11: =Table1[[#This Row],[Termékkör]] -> Rakományrögzítők | G11: =Table1[[#This Row],[SzumElad]] -> 9700 | H11: =Table1[[#This Row],[Jut_%]] -> 13.09 | I11: =Table1[[#This Row],[Jut]] -> 1269.73 | J11: =Table1[[#This Row],[Column1]] -> 0
A12: =Table1[[#This Row],[Befolyt]] -> n | B12: =Table1[[#This Row],[ÜK]] -> Négyesy Gábor | C12: =Table1[[#This Row],[Szla]] -> 727/2026 | D12: =Table1[[#This Row],[Kelt_hó]] -> 2 | E12: =Table1[[#This Row],[Vevő]] -> Pro Grip Kft. | F12: =Table1[[#This Row],[Termékkör]] -> Rakományrögzítők | G12: =Table1[[#This Row],[SzumElad]] -> 970 | H12: =Table1[[#This Row],[Jut_%]] -> 13.09 | I12: =Table1[[#This Row],[Jut]] -> 126.973 | J12: =Table1[[#This Row],[Column1]] -> 0
A13: =Table1[[#This Row],[Befolyt]] -> n | B13: =Table1[[#This Row],[ÜK]] -> Négyesy Gábor | C13: =Table1[[#This Row],[Szla]] -> 727/2026 | D13: =Table1[[#This Row],[Kelt_hó]] -> 2 | E13: =Table1[[#This Row],[Vevő]] -> Pro Grip Kft. | F13: =Table1[[#This Row],[Termékkör]] -> Rakományrögzítők | G13: =Table1[[#This Row],[SzumElad]] -> 9630 | H13: =Table1[[#This Row],[Jut_%]] -> 12.8 | I13: =Table1[[#This Row],[Jut]] -> 1232.64 | J13: =Table1[[#This Row],[Column1]] -> 0
... A10000: =Table1[[#This Row],[Befolyt]] -> #VALUE! | B10000: =Table1[[#This Row],[ÜK]] -> #VALUE! | C10000: =Table1[[#This Row],[Szla]] -> #VALUE! | D10000: =Table1[[#This Row],[Kelt_hó]] -> #VALUE! | E10000: =Table1[[#This Row],[Vevő]] -> #VALUE! | F10000: =Table1[[#This Row],[Termékkör]] -> #VALUE! | G10000: =Table1[[#This Row],[SzumElad]] -> #VALUE! | H10000: =Table1[[#This Row],[Jut_%]] -> #VALUE! | I10000: =Table1[[#This Row],[Jut]] -> #VALUE! | J10000: =Table1[[#This Row],[Column1]] -> #VALUE!
G10001: =SUBTOTAL(109,Table2[FIZET]) -> 2709512 | I10001: =SUBTOTAL(109,Table2[JUT]) -> 151795.85

Sheet SumElad
A3: Sum of SzumElad | B3: Column Labels
A4: Row Labels | B4: 1 | C4: 2 | D4: Grand Total
A5: Alap | B5: 53421395 | C5: 95674707 | D5: 1.490961e+08
A6: Acélsodrony függesztékek | B6: 377670 | C6: 1690792 | D6: 2068462
A7: Adapterek | C7: 431854.22 | D7: 431854.22
A8: Darukötelek | B8: 649120 | C8: 1421275 | D8: 2070395
A9: Emelőgerenda adapter | C9: 125000 | D9: 125000
A10: Emelőmágnesek | B10: 1143946 | C10: 5061631.2 | D10: 6205577.2
A11: Emelőszemek | B11: 330660 | C11: 939865 | D11: 1270525
A12: Emelőszerkezetek | B12: 4865723.9 | C12: 5362125.5 | D12: 10227849
A13: Garázsipari felszerelések | B13: 270000 | D13: 270000
A14: Kapcsolóelemek | B14: 2802424.8 | C14: 1581005.2 | D14: 4383430
A15: Lánc függesztékek | B15: 5805570.8 | C15: 10719192 | D15: 16524763
A16: Leesés elleni védelem | B16: 551900 | C16: 259010 | D16: 810910
A17: Megfogók | B17: 2866019.4 | C17: 3878943.6 | D17: 6744963.1
A18: Rakományrögzítők | B18: 4987849 | C18: 31504543 | D18: 36492392
A19: Textilkötelek hevederek | B19: 18149000 | C19: 11337538 | D19: 29486538
A20: Vizsgálat | B20: 10621511 | C20: 21361932 | D20: 31983444
A21: Beruházás | B21: 17512728 | C21: 25180134 | D21: 42692862
A22: Daruk futómacskák | B22: 2508238.6 | C22: 14610140 | D22: 17118379
A23: Emelőberendezések | B23: 9365725.2 | C23: 7048785.2 | D23: 16414510
A24: Emelőgép szolgáltatások | B24: 5638764.5 | C24: 2767947.5 | D24: 8406712
A25: Emelőszerkezetek | C25: 753261.08 | D25: 753261.08
A26: Egyéb | B26: 1441430.6 | C26: 3777763.2 | D26: 5219193.8
A27: Egyéb | B27: 26000 | C27: 78000 | D27: 104000
A28: Emelőgép szolgáltatások | B28: 139981 | C28: 1589870.2 | D28: 1729851.2
A29: Fuvar | B29: 238501.57 | C29: 723195.04 | D29: 961696.61
A30: Kiszállás | B30: 748348 | C30: 1042298 | D30: 1790646
A31: Saját munka | B31: 288600 | C31: 344400 | D31: 633000
A32: Előleg | B32: 11777812 | C32: -7652291.8 | D32: 4125520.4
A33: Előleg | B33: 11777812 | C33: -7652291.8 | D33: 4125520.4
A34: #N/A | C34: 88110 | D34: 88110
A35: Emelőszerkezetek | C35: 88110 | D35: 88110
A36: Grand Total | B36: 84153366 | C36: 1.1706842e+08 | D36: 2.0122179e+08

Sheet Árrések
A3: Sum of Árrés
B4: 1 | C4: 2 | D4: Grand Total
A5: Alap | B5: 26532784 | C5: 41031841 | D5: 67564625
A6: Acélsodrony függesztékek | B6: 134929.43 | C6: 593073.88 | D6: 728003.31
A7: Adapterek | B7: 0 | C7: 126849.22 | D7: 126849.22
A8: Darukötelek | B8: 282240.2 | C8: 572078.04 | D8: 854318.24
A9: Emelőgerenda adapter | B9: 0 | C9: 71337.71 | D9: 71337.71
A10: Emelőmágnesek | B10: 548905.36 | C10: 2324640.5 | D10: 2873545.9
A11: Emelőszemek | B11: 156258.76 | C11: 413172.35 | D11: 569431.11
A12: Emelőszerkezetek | B12: 1397535.4 | C12: 2039700.5 | D12: 3437235.8
A13: Garázsipari felszerelések | B13: 124949.75 | C13: 0 | D13: 124949.75
A14: Kapcsolóelemek | B14: 1219329.9 | C14: 575472.42 | D14: 1794802.3
A15: Lánc függesztékek | B15: 3625797.6 | C15: 5624812.6 | D15: 9250610.2
A16: Leesés elleni védelem | B16: 237926.24 | C16: 105069.17 | D16: 342995.41
... A36: Grand Total | B36: 38248483 | C36: 41013328 | D36: 79261811

Sheet MB-hez Árrés
C4: Sum of Árrés | D4: Kelt_hó | E4: Termékfajta
D5: 1 | H5: 1 Total | I5: 2 | N5: 2 Total | O5: Grand Total
C6: ÜK | D6: Alap | E6: Beruházás | F6: Egyéb | G6: Előleg | I6: Alap | J6: Beruházás | K6: Egyéb | L6: Előleg | M6: #N/A
C7: Bálint Miklós | D7: 686378.91 | E7: 896184.18 | F7: -40686.04 | G7: 0 | H7: 1541877.1 | I7: 821627.94 | J7: 226412.07 | K7: -52784.5 | L7: 0 | M7: 0 | N7: 995255.51 | O7: 2537132.6
C8: Forgó Tamás | D8: 110088.93 | E8: 0 | F8: 0 | G8: 0 | H8: 110088.93 | I8: 8759768 | J8: 0 | K8: 22815.36 | L8: 0 | M8: 0 | N8: 8782583.4 | O8: 8892672.3
C9: Halász Miklós | D9: 4121325.7 | E9: 153088 | F9: 39833.21 | G9: 0 | H9: 4314247 | I9: 3653370.5 | J9: 0 | K9: -147959.34 | L9: 0 | M9: 0 | N9: 3505411.2 | O9: 7819658.1
C10: Hegyi Gábor | D10: 909936.82 | E10: 907568.75 | F10: 9598 | G10: 0 | H10: 1827103.6 | I10: 2437072.3 | J10: 140212.86 | K10: -12831.54 | L10: 194940.16 | M10: 0 | N10: 2759393.8 | O10: 4586497.4
C11: Horváth István | D11: 1640375.6 | E11: 709754.24 | F11: -67856.48 | G11: 3796621.5 | H11: 6078894.9 | I11: 1983878.6 | J11: 0 | K11: 39839.94 | L11: 0 | M11: 0 | N11: 2023718.5 | O11: 8102613.4
C12: Molnár Ferenc | D12: 2979753.9 | E12: 62622.162 | F12: -15036.29 | G12: 981190.75 | H12: 4008530.6 | I12: 3620337.5 | J12: 730169.57 | K12: -124904.9 | L12: 0 | M12: 0 | N12: 4225602.2 | O12: 8234132.8
C13: Nagy Gergely | D13: 9647009.2 | E13: -695.42 | F13: 68671 | G13: 0 | H13: 9714984.8 | I13: 4403677.3 | J13: 391621.38 | K13: -2248.896 | L13: 0 | M13: 0 | N13: 4793049.8 | O13: 14508035
C14: Négyesy Gábor | D14: 3770941.3 | E14: 284428.8 | F14: 101032.43 | G14: 0 | H14: 4156402.6 | I14: 9933374.1 | J14: 717777.63 | K14: 95593.644 | L14: 0 | M14: 47539.253 | N14: 10794285 | O14: 14950687
C15: Simon Jenő | D15: 1130948.8 | E15: 0 | F15: -25332.04 | G15: 0 | H15: 1105616.8 | I15: 2199829 | J15: 3855249.8 | K15: 179133.88 | L15: -8947232 | M15: 0 | N15: -2713019.3 | O15: -1607402.6
C16: Horváth István. | D16: 374577.05 | E16: 461668.07 | F16: -31132 | G16: 0 | H16: 805113.12 | I16: 1049677.9 | J16: 20626.85 | K16: -5836.05 | L16: 0 | M16: 0 | N16: 1064468.7 | O16: 1869581.8
C17: Grand Total | D17: 25371336 | E17: 3474618.8 | F17: 39091.788 | G17: 4777812.2 | H17: 33662859 | I17: 38862613 | J17: 6082070.2 | K17: -9182.4 | L17: -8752291.8 | M17: 47539.253 | N17: 36230748 | O17: 69893608

Sheet KTGC-hez
C4: Sum of SzumElad | E4: Kelt_hó
C5: Termékfajta | D5: ÜK | E5: 1 | F5: 2 | G5: Grand Total
C6: Alap | D6: Négyesy Gábor | E6: 8381203 | F6: 18847813 | G6: 27229016
D7: Nagy Gergely | E7: 15910377 | F7: 10579148 | G7: 26489525
D8: Forgó Tamás | E8: 220981.05 | F8: 24865810 | G8: 25086791
D9: Halász Miklós | E9: 7830321 | F9: 6234648 | G9: 14064969
D10: Molnár Ferenc | E10: 6002720 | F10: 6828932 | G10: 12831652
D11: Tóth Ferenc | E11: 6393877.4 | F11: 1740722.6 | G11: 8134600
D12: Simon Jenő | E12: 2117795.1 | F12: 5891967.3 | G12: 8009762.5
D13: Hegyi Gábor | E13: 1708130 | F13: 5479049 | G13: 7187179
D14: Horváth István | E14: 2458854 | F14: 3512887 | G14: 5971741
D15: Vlada Gasić | F15: 5127366.7 | G15: 5127366.7
D16: Bálint Miklós | E16: 1205612 | F16: 2613860 | G16: 3819472
D17: Horváth István. | E17: 565326 | F17: 1829316.5 | G17: 2394642.5
D18: Kocsis Károly | E18: 100625 | F18: 892400 | G18: 993025
D19: Buzás Péter | E19: 43332.6 | F19: 914922.74 | G19: 958255.34
D20: H-ITB Kft. | E20: 482240.32 | F20: 315865 | G20: 798105.32
C21: Alap Total | E21: 53421395 | F21: 95674707 | G21: 1.490961e+08
C22: Beruházás | D22: Simon Jenő | F22: 16950573 | G22: 16950573
D23: H-ITB Kft. | E23: 8324721.2 | F23: 1454400 | G23: 9779121.2
D24: Négyesy Gábor | E24: 1861280 | F24: 2061701.1 | G24: 3922981.1
D25: Hegyi Gábor | E25: 2352700 | F25: 449125.5 | G25: 2801825.5
D26: Bálint Miklós | E26: 1379200 | F26: 823100 | G26: 2202300
D27: Molnár Ferenc | E27: 145826.36 | F27: 1982154.9 | G27: 2127981.2
D28: Horváth István | E28: 1757750 | G28: 1757750
D29: Horváth István. | E29: 1215944.7 | F29: 47168.75 | G29: 1263113.5
D30: Nagy Gergely | E30: 0 | F30: 1050102 | G30: 1050102
D31: Halász Miklós | E31: 367800 | G31: 367800
D32: Vlada Gasić | F32: 361808.29 | G32: 361808.29
D33: Buzás Péter | E33: 107506 | G33: 107506
C34: Beruházás Total | E34: 17512728 | F34: 25180134 | G34: 42692862
C35: Egyéb | D35: Simon Jenő | E35: 46800 | F35: 1592440.2 | G35: 1639240.2
D36: H-ITB Kft. | E36: 130679 | F36: 603680 | G36: 734359
D37: Négyesy Gábor | E37: 276338 | F37: 264948 | G37: 541286
D38: Hegyi Gábor | E38: 139600 | F38: 280500 | G38: 420100
D39: Forgó Tamás | F39: 410596.55 | G39: 410596.55
D40: Halász Miklós | E40: 308685 | F40: 47069 | G40: 355754
D41: Molnár Ferenc | E41: 176998 | F41: 137317 | G41: 314315
D42: Nagy Gergely | E42: 170000 | F42: 43800 | G42: 213800
D43: Bálint Miklós | E43: 124700 | F43: 54626 | G43: 179326
...

Sheet KTGC
A1: UZL | B1: ÜK | C1: Jan | D1: Febr | E1: Márc | F1: Ápr | G1: Máj | H1: Jún | I1: Júl | J1: Aug | K1: Szept | L1: Okt | M1: Nov | N1: Dec | O1: SZUM | T1: Alap | U1: Ber
Q2: 2024 | S2: havi alapterv
A3: Polyák | B3: ELAD 26 | C3: =C10+C11 -> 10518821 | D3: =D10+D11 -> 21174462 | E3: =E10+E11 -> #REF! | F3: =F10+F11 -> #REF! | G3: =G10+G11 -> #REF! | H3: =H10+H11 -> #REF! | I3: =I10+I11 -> #REF! | J3: =J10+J11 -> #REF! | ... N3: =N10+N11 -> #REF! | O3: =SUM(C3:N3) -> #REF! | Q3: Min. Terv | R3: Alap limit | S3: BonuszLimit | T3: AlapTerv | U3: Egyéb
A4: Polyák | B4: TERV 26 | C4: =$O4/12 -> 21250000 | D4: =$O4/12 -> 21250000 | E4: =$O4/12 -> 21250000 | F4: =$O4/12 -> 21250000 | G4: =$O4/12 -> 21250000 | H4: =$O4/12 -> 21250000 | I4: =$O4/12 -> 21250000 | J4: =$O4/12 -> 21250000 | ... N4: =$O4/12 -> 21250000 | O4: =T4+U4 -> 255000000 | Q4: =O4/12*0.9 -> 19125000 | R4: =T4/12*0.9 -> 15750000 | S4: =ROUNDUP(T4/12,-5) -> 17500000 | T4: 210000000 | U4: 45000000
A5: Polyák | O5: =T4+T6 -> 255000000 | T5: BerTerv | U5: Ber_hó
A6: Polyák | B6: TÉNY 26/TERV 26 | C6: =C3/C4 -> 0.49500334 | D6: =D3/D4 -> 0.99644526 | E6: =E3/E4 -> #REF! | F6: =F3/F4 -> #REF! | G6: =G3/G4 -> #REF! | H6: =H3/H4 -> #REF! | I6: =I3/I4 -> #REF! | J6: =J3/J4 -> #REF! | ... O6: =O3/O4 -> #REF! | T6: 45000000 | U6: =T6/12 -> 3750000
A7: Polyák | B7: KORRIGÁLT 26 | O7: =SUM(C7:N7) -> 0
A8: Polyák | B8: 6 % TÉNY 26 | Q8: Bonusz: | R8: Ha Elad < Min. Terv => Bonusz = 0
A9: Polyák | B9: Bonusz_26 | C9: =IF(C10<$R4,0,IF(C3<$Q4,0,IF(C3>C4,IF(C10>$S4,500000,500000*(C10/$S4)*(C10/$S4) ),(C3-$Q4)/(C4-$Q4)*500000))) -> 0 | D9: =IF(D10<$R4,0,IF(D3<$Q4,0,IF(D3>D4,IF(D10>$S4,500000,500000*(D10/$S4)*(D10/$S4) ),(D3-$Q4)/(D4-$Q4)*500000))) -> 482226.3 | E9: =IF(E10<$R4,0,IF(E3<$Q4,0,IF(E3>E4,IF(E10>$S4,500000,500000*(E10/$S4)*(E10/$S4) ),(E3-$Q4)/(E4-$Q4)*500000))) -> #REF! | F9: =IF(F10<$R4,0,IF(F3<$Q4,0,IF(F3>F4,IF(F10>$S4,500000,500000*(F10/$S4)*(F10/$S4) ),(F3-$Q4)/(F4-$Q4)*500000))) -> #REF! | G9: =IF(G10<$R4,0,IF(G3<$Q4,0,IF(G3>G4,IF(G10>$S4,500000,500000*(G10/$S4)*(G10/$S4) ),(G3-$Q4)/(G4-$Q4)*500000))) -> #REF! | H9: =IF(H10<$R4,0,IF(H3<$Q4,0,IF(H3>H4,IF(H10>$S4,500000,500000*(H10/$S4)*(H10/$S4) ),(H3-$Q4)/(H4-$Q4)*500000))) -> #REF! | I9: =IF(I10<$R4,0,IF(I3<$Q4,0,IF(I3>I4,IF(I10>$S4,500000,500000*(I10/$S4)*(I10/$S4) ),(I3-$Q4)/(I4-$Q4)*500000))) -> #REF! | J9: =IF(J10<$R4,0,IF(J3<$Q4,0,IF(J3>J4,IF(J10>$S4,500000,500000*(J10/$S4)*(J10/$S4) ),(J3-$Q4)/(J4-$Q4)*500000))) -> #REF! | ... N9: =IF(N10<$R4,0,IF(N3<$Q4,0,IF(N3>N4,IF(N10>$S4,500000,500000*(N10/$S4)*(N10/$S4) ),(N3-$Q4)/(N4-$Q4)*500000))) -> #REF! | O9: =SUM(C9:N9) -> #REF! | R9: Ha Alap < Alap Limit(13M) => Bonusz = 0
A10: Polyák | B10: Alap_26 | C10: =GETPIVOTDATA("SzumElad",'KTGC-hez'!$C$4,"Kelt_hó",1,"Termékfajta","Alap","ÜK","Négyesy Gábor") -> 8381203 | D10: =GETPIVOTDATA("SzumElad",'KTGC-hez'!$C$4,"Kelt_hó",2,"Termékfajta","Alap","ÜK","Négyesy Gábor") -> 18847813 | E10: =GETPIVOTDATA("SzumElad",'KTGC-hez'!$C$4,"Kelt_hó",3,"Termékfajta","Alap","ÜK","Négyesy Gábor") -> #REF! | F10: =GETPIVOTDATA("SzumElad",'KTGC-hez'!$C$4,"Kelt_hó",4,"Termékfajta","Alap","ÜK","Négyesy Gábor") -> #REF! | G10: =GETPIVOTDATA("SzumElad",'KTGC-hez'!$C$4,"Kelt_hó",5,"Termékfajta","Alap","ÜK","Négyesy Gábor") -> #REF! | H10: =GETPIVOTDATA("SzumElad",'KTGC-hez'!$C$4,"Kelt_hó",6,"Termékfajta","Alap","ÜK","Négyesy Gábor") -> #REF! | I10: =GETPIVOTDATA("SzumElad",'KTGC-hez'!$C$4,"Kelt_hó",7,"Termékfajta","Alap","ÜK","Négyesy Gábor") -> #REF! | J10: =GETPIVOTDATA("SzumElad",'KTGC-hez'!$C$4,"Kelt_hó",8,"Termékfajta","Alap","ÜK","Négyesy Gábor") -> #REF! | K10: =GETPIVOTDATA("SzumElad",'KTGC-hez'!$C$4,"Kelt_hó",9,"Termékfajta","Alap","ÜK","Négyesy Gábor") -> #REF! | L10: =GETPIVOTDATA("SzumElad",'KTGC-hez'!$C$4,"Kelt_hó",10,"Termékfajta","Alap","ÜK","Négyesy Gábor") -> #REF! | M10: =GETPIVOTDATA("SzumElad",'KTGC-hez'!$C$4,"Kelt_hó",11,"Termékfajta","Alap","ÜK","Négyesy Gábor") -> #REF! | N10: =GETPIVOTDATA("SzumElad",'KTGC-hez'!$C$4,"Kelt_hó",12,"Termékfajta","Alap","ÜK","Négyesy Gábor") -> #REF! | O10: =SUM(C10:N10) -> #REF! | R10: Ha Elad > Terv és Alap > BonuszLimit => Bonusz = 500 000 | X10: =IFERROR(D10,0) -> 18847813
A11: Polyák | B11: Ber_25 | C11: =GETPIVOTDATA("SzumElad",'KTGC-hez'!$C$4,"Kelt_hó",1,"Termékfajta","Beruházás","ÜK","Négyesy Gábor")+GETPIVOTDATA("SzumElad",'KTGC-hez'!$C$4,"Kelt_hó",1,"Termékfajta","Egyéb","ÜK","Négyesy Gábor") -> 2137618 | D11: =GETPIVOTDATA("SzumElad",'KTGC-hez'!$C$4,"Kelt_hó",2,"Termékfajta","Beruházás","ÜK","Négyesy Gábor")+GETPIVOTDATA("SzumElad",'KTGC-hez'!$C$4,"Kelt_hó",2,"Termékfajta","Egyéb","ÜK","Négyesy Gábor") -> 2326649.1 | E11: =GETPIVOTDATA("SzumElad",'KTGC-hez'!$C$4,"Kelt_hó",3,"Termékfajta","Beruházás","ÜK","Négyesy Gábor")+GETPIVOTDATA("SzumElad",'KTGC-hez'!$C$4,"Kelt_hó",3,"Termékfajta","Egyéb","ÜK","Négyesy Gábor") -> #REF! | F11: =GETPIVOTDATA("SzumElad",'KTGC-hez'!$C$4,"Kelt_hó",4,"Termékfajta","Beruházás","ÜK","Négyesy Gábor")+GETPIVOTDATA("SzumElad",'KTGC-hez'!$C$4,"Kelt_hó",4,"Termékfajta","Egyéb","ÜK","Négyesy Gábor") -> #REF! | G11: =GETPIVOTDATA("SzumElad",'KTGC-hez'!$C$4,"Kelt_hó",5,"Termékfajta","Beruházás","ÜK","Négyesy Gábor")+GETPIVOTDATA("SzumElad",'KTGC-hez'!$C$4,"Kelt_hó",5,"Termékfajta","Egyéb","ÜK","Négyesy Gábor") -> #REF! | H11: =GETPIVOTDATA("SzumElad",'KTGC-hez'!$C$4,"Kelt_hó",6,"Termékfajta","Beruházás","ÜK","Négyesy Gábor")+GETPIVOTDATA("SzumElad",'KTGC-hez'!$C$4,"Kelt_hó",6,"Termékfajta","Egyéb","ÜK","Négyesy Gábor") -> #REF! | I11: =GETPIVOTDATA("SzumElad",'KTGC-hez'!$C$4,"Kelt_hó",7,"Termékfajta","Beruházás","ÜK","Négyesy Gábor")+GETPIVOTDATA("SzumElad",'KTGC-hez'!$C$4,"Kelt_hó",7,"Termékfajta","Egyéb","ÜK","Négyesy Gábor") -> #REF! | J11: =GETPIVOTDATA("SzumElad",'KTGC-hez'!$C$4,"Kelt_hó",8,"Termékfajta","Beruházás","ÜK","Négyesy Gábor")+GETPIVOTDATA("SzumElad",'KTGC-hez'!$C$4,"Kelt_hó",8,"Termékfajta","Egyéb","ÜK","Négyesy Gábor") -> #REF! | K11: =GETPIVOTDATA("SzumElad",'KTGC-hez'!$C$4,"Kelt_hó",9,"Termékfajta","Beruházás","ÜK","Négyesy Gábor")+GETPIVOTDATA("SzumElad",'KTGC-hez'!$C$4,"Kelt_hó",9,"Termékfajta","Egyéb","ÜK","Négyesy Gábor") -> #REF! | L11: =GETPIVOTDATA("SzumElad",'KTGC-hez'!$C$4,"Kelt_hó",10,"Termékfajta","Beruházás","ÜK","Négyesy Gábor")+GETPIVOTDATA("SzumElad",'KTGC-hez'!$C$4,"Kelt_hó",10,"Termékfajta","Egyéb","ÜK","Négyesy Gábor") -> #REF! | M11: =GETPIVOTDATA("SzumElad",'KTGC-hez'!$C$4,"Kelt_hó",11,"Termékfajta","Beruházás","ÜK","Négyesy Gábor")+GETPIVOTDATA("SzumElad",'KTGC-hez'!$C$4,"Kelt_hó",11,"Termékfajta","Egyéb","ÜK","Négyesy Gábor") -> #REF! | N11: =GETPIVOTDATA("SzumElad",'KTGC-hez'!$C$4,"Kelt_hó",12,"Termékfajta","Beruházás","ÜK","Négyesy Gábor")+GETPIVOTDATA("SzumElad",'KTGC-hez'!$C$4,"Kelt_hó",12,"Termékfajta","Egyéb","ÜK","Négyesy Gábor") -> #REF! | O11: =SUM(C11:N11) -> #REF! | R11: Ha Elad > Terv és Alap < BonuszLimit => Bonusz = 500 000 * (Alap/BonuszLimit)²
A12: Polyák | B12: Kumulált_ber | E12: =C11+D11+E11 -> #REF! | H12: =F11+G11+H11 -> #REF! | K12: =I11+J11+K11 -> #REF! | N12: =L11+M11+N11 -> #REF! | R12: Ha Elad < Terv de Elad > Min. Terv => Bonusz = 500 000 * (Elad - min.Terv)/(Terv - min.Terv)
A13: Polyák | B13: Kumulált_ber_terv | E13: =$U6*3 -> 11250000 | H13: =$U6*3 -> 11250000 | K13: =$U6*3 -> 11250000 | N13: =$U6*3 -> 11250000
A14: Polyák | B14: BerBon | E14: 0 | H14: =IF(H12>H13,180000,IF(H12>H13*0.9,100000,IF(H12>H13*0.75,60000,0))) -> #REF! | K14: =IF(K12>K13,180000,IF(K12>K13*0.9,100000,IF(K12>K13*0.75,60000,0))) -> #REF! | N14: =IF(N12>N13,180000,IF(N12>N13*0.9,100000,IF(N12>N13*0.75,60000,0))) -> #REF! | Q14: BerBon: | R14: Ha 3 havi Ber min. 75%os => 60 000
A15: Polyák | B15: KTGC_26 | C15: =C7+C9+C14 -> 0 | D15: =D7+D9+D14 -> 482226.3 | E15: =E7+E9+E14 -> #REF! | F15: =F7+F9+F14 -> #REF! | G15: =G7+G9+G14 -> #REF! | H15: =H7+H9+H14 -> #REF! | I15: =I7+I9+I14 -> #REF! | J15: =J7+J9+J14 -> #REF! | ... N15: =N7+N9+N14 -> #REF! | O15: =SUM(C15:N15) -> #REF! | R15: 90%-os => 100 000; 100%-os => 180 000
A16: Polyák | B16: JUT_26 | C16: 110239 | D16: 812989 | O16: =SUM(C16:N16) -> 923228
B17: SZUM | C17: =SUM(C15:C16) -> 110239 | D17: =SUM(D15:D16) -> 1295215.3 | E17: =SUM(E15:E16) -> #REF! | F17: =SUM(F15:F16) -> #REF! | G17: =SUM(G15:G16) -> #REF! | H17: =SUM(H15:H16) -> #REF! | I17: =SUM(I15:I16) -> #REF! | J17: =SUM(J15:J16) -> #REF! | ... O17: =SUM(O15:O16) -> #REF!
B18: JUT_25 | C18: 1395544 | D18: 332694
C19: =C18+C17 -> 1505783 | D19: =D18+D17 -> 1627909.3 | E19: =E18+E17 -> #REF! | F19: =F18+F17 -> #REF! | G19: =G18+G17 -> #REF! | H19: =H18+H17 -> #REF! | I19: =I18+I17 -> #REF! | J19: =J18+J17 -> #REF! | ... N19: =N18+N17 -> #REF!
A22: UZL | B22: ÜK | C22: Jan | D22: Febr | E22: Márc | F22: Ápr | G22: Máj | H22: Jún | I22: Júl | J22: Aug | K22: Szept | L22: Okt | M22: Nov | N22: Dec | O22: SZUM | T22: Alap | U22: Ber
Q23: 2025 | R23: havi alapterv*0,9 | S23: havi alapterv
A24: GNAGY | B24: ELAD 26 | C24: =C31+C32 -> 15910377 | D24: =D31+D32 -> 11629250 | E24: =E31+E32 -> #REF! | F24: =F31+F32 -> #REF! | G24: =G31+G32 -> #REF! | H24: =H31+H32 -> #REF! | I24: =I31+I32 -> #REF! | J24: =J31+J32 -> #REF! | ... N24: =N31+N32 -> #REF! | O24: =SUM(C24:N24) -> #REF! | Q24: Min. Terv | R24: 360 LIMIT | S24: BonuszLimit | T24: AlapTerv | U24: Egyéb
A25: GNAGY | B25: TERV 26 | C25: =$O25/12 -> 12916667 | D25: =$O25/12 -> 12916667 | E25: =$O25/12 -> 12916667 | F25: =$O25/12 -> 12916667 | G25: =$O25/12 -> 12916667 | H25: =$O25/12 -> 12916667 | I25: =$O25/12 -> 12916667 | J25: =$O25/12 -> 12916667 | ... N25: =$O25/12 -> 12916667 | O25: =T25+U25 -> 155000000 | Q25: =O25/12*0.9 -> 11625000 | R25: =T25/12*0.9 -> 8625000 | S25: =ROUNDUP(T25/12,-5) -> 9600000 | T25: 115000000 | U25: 40000000
A26: GNAGY | O26: =T25+T27 -> 155000000 | T26: BerTerv | U26: Ber_hó
A27: GNAGY | B27: TÉNY 26/TERV 26 | C27: =C24/C25 -> 1.2317711 | D27: =D24/D25 -> 0.90032903 | E27: =E24/E25 -> #REF! | F27: =F24/F25 -> #REF! | G27: =G24/G25 -> #REF! | H27: =H24/H25 -> #REF! | I27: =I24/I25 -> #REF! | J27: =J24/J25 -> #REF! | ... O27: =O24/O25 -> #REF! | T27: 40000000 | U27: =T27/12 -> 3333333.3
A28: GNAGY | B28: KORRIGÁLT 26 | C28: =IF(C24=Z28,0,IF(C29<180000,IF(C31< 1500000, 100000,180000),IF(C31>$R25,360000,C29))) -> 360000 | D28: =IF(D24=AA28,0,IF(D29<180000,IF(D31< 1500000, 100000,180000),IF(D31>$R25,360000,D29))) -> 360000 | E28: =IF(E24=AB28,0,IF(E29<180000,IF(E31< 1500000, 100000,180000),IF(E31>$R25,360000,E29))) -> #REF! | F28: =IF(F24=AC28,0,IF(F29<180000,IF(F31< 1500000, 100000,180000),IF(F31>$R25,360000,F29))) -> #REF! | G28: =IF(G24=AD28,0,IF(G29<180000,IF(G31< 1500000, 100000,180000),IF(G31>$R25,360000,G29))) -> #REF! | H28: =IF(H24=AE28,0,IF(H29<180000,IF(H31< 1500000, 100000,180000),IF(H31>$R25,360000,H29))) -> #REF! | I28: =IF(I24=AF28,0,IF(I29<180000,IF(I31< 1500000, 100000,180000),IF(I31>$R25,360000,I29))) -> #REF! | J28: =IF(J24=AG28,0,IF(J29<180000,IF(J31< 1500000, 100000,180000),IF(J31>$R25,360000,J29))) -> #REF! | ... N28: =IF(N24=AK28,0,IF(N29<180000,IF(N31< 1500000, 100000,180000),IF(N31>$R25,360000,N29))) -> #REF! | O28: =SUM(C28:N28) -> #REF!
A29: GNAGY | B29: 6 % TÉNY 26 | C29: =IF(C24*0.06*C27>300000,300000,IF(C31<1500000,100000,C24*0.06*C27)) -> 300000 | D29: =IF(D24*0.06*D27>300000,300000,IF(D31<1500000,100000,D24*0.06*D27)) -> 300000 | E29: =IF(E24*0.06*E27>300000,300000,IF(E31<1500000,100000,E24*0.06*E27)) -> #REF! | F29: =IF(F24*0.06*F27>300000,300000,IF(F31<1500000,100000,F24*0.06*F27)) -> #REF! | G29: =IF(G24*0.06*G27>300000,300000,IF(G31<1500000,100000,G24*0.06*G27)) -> #REF! | H29: =IF(H24*0.06*H27>300000,300000,IF(H31<1500000,100000,H24*0.06*H27)) -> #REF! | I29: =IF(I24*0.06*I27>300000,300000,IF(I31<1500000,100000,I24*0.06*I27)) -> #REF! | J29: =IF(J24*0.06*J27>300000,300000,IF(J31<1500000,100000,J24*0.06*J27)) -> #REF! | ... N29: =IF(N24*0.06*N27>300000,300000,IF(N31<1500000,100000,N24*0.06*N27)) -> #REF! | Q29: KTGC : | R29: ELAD * (TÉNY/TERV) * 0,06 (max 300 000)
A30: GNAGY | B30: Bonusz_26 | C30: =IF(C31<$S25,0,IF(C24<$Q25,0,IF(C24>C25,120000,(C24-$Q25)/(C25-$Q25)*120000))) -> 120000 | D30: =IF(D31<$S25,0,IF(D24<$Q25,0,IF(D24>D25,120000,(D24-$Q25)/(D25-$Q25)*120000))) -> 394.83499 | E30: =IF(E31<$S25,0,IF(E24<$Q25,0,IF(E24>E25,120000,(E24-$Q25)/(E25-$Q25)*120000))) -> #REF! | F30: =IF(F31<$S25,0,IF(F24<$Q25,0,IF(F24>F25,120000,(F24-$Q25)/(F25-$Q25)*120000))) -> #REF! | G30: =IF(G31<$S25,0,IF(G24<$Q25,0,IF(G24>G25,120000,(G24-$Q25)/(G25-$Q25)*120000))) -> #REF! | H30: =IF(H31<$S25,0,IF(H24<$Q25,0,IF(H24>H25,120000,(H24-$Q25)/(H25-$Q25)*120000))) -> #REF! | I30: =IF(I31<$S25,0,IF(I24<$Q25,0,IF(I24>I25,120000,(I24-$Q25)/(I25-$Q25)*120000))) -> #REF! | J30: =IF(J31<$S25,0,IF(J24<$Q25,0,IF(J24>J25,120000,(J24-$Q25)/(J25-$Q25)*120000))) -> #REF! | ... N30: =IF(N31<$S25,0,IF(N24<$Q25,0,IF(N24>N25,120000,(N24-$Q25)/(N25-$Q25)*120000))) -> #REF! | O30: =SUM(C30:N30) -> #REF! | Q30: KorrigáltKTGC: | R30: Ha KTGC < 180 000 lenne de Alap !< 1 500 000 akkor KTGC 180 000
A31: GNAGY | B31: Alap_26 | C31: =GETPIVOTDATA("SzumElad",'KTGC-hez'!$C$4,"Kelt_hó",1,"Termékfajta","Alap","ÜK","Nagy Gergely") -> 15910377 | D31: =GETPIVOTDATA("SzumElad",'KTGC-hez'!$C$4,"Kelt_hó",2,"Termékfajta","Alap","ÜK","Nagy Gergely") -> 10579148 | E31: =GETPIVOTDATA("SzumElad",'KTGC-hez'!$C$4,"Kelt_hó",3,"Termékfajta","Alap","ÜK","Nagy Gergely") -> #REF! | F31: =GETPIVOTDATA("SzumElad",'KTGC-hez'!$C$4,"Kelt_hó",4,"Termékfajta","Alap","ÜK","Nagy Gergely") -> #REF! | G31: =GETPIVOTDATA("SzumElad",'KTGC-hez'!$C$4,"Kelt_hó",5,"Termékfajta","Alap","ÜK","Nagy Gergely") -> #REF! | H31: =GETPIVOTDATA("SzumElad",'KTGC-hez'!$C$4,"Kelt_hó",6,"Termékfajta","Alap","ÜK","Nagy Gergely") -> #REF! | I31: =GETPIVOTDATA("SzumElad",'KTGC-hez'!$C$4,"Kelt_hó",7,"Termékfajta","Alap","ÜK","Nagy Gergely") -> #REF! | J31: =GETPIVOTDATA("SzumElad",'KTGC-hez'!$C$4,"Kelt_hó",8,"Termékfajta","Alap","ÜK","Nagy Gergely") -> #REF! | K31: =GETPIVOTDATA("SzumElad",'KTGC-hez'!$C$4,"Kelt_hó",9,"Termékfajta","Alap","ÜK","Nagy Gergely") -> #REF! | L31: =GETPIVOTDATA("SzumElad",'KTGC-hez'!$C$4,"Kelt_hó",10,"Termékfajta","Alap","ÜK","Nagy Gergely") -> #REF! | M31: =GETPIVOTDATA("SzumElad",'KTGC-hez'!$C$4,"Kelt_hó",11,"Termékfajta","Alap","ÜK","Nagy Gergely") -> #REF! | N31: =GETPIVOTDATA("SzumElad",'KTGC-hez'!$C$4,"Kelt_hó",12,"Termékfajta","Alap","ÜK","Nagy Gergely") -> #REF! | O31: =SUM(C31:N31) -> #REF! | R31: Ha Alap< 1 500 000 => KTGC = 100 000
A32: GNAGY | B32: Ber_25 | C32: =GETPIVOTDATA("SzumElad",'KTGC-hez'!$C$4,"Kelt_hó",1,"Termékfajta","Beruházás","ÜK","Nagy Gergely") -> 0 | D32: =GETPIVOTDATA("SzumElad",'KTGC-hez'!$C$4,"Kelt_hó",2,"Termékfajta","Beruházás","ÜK","Nagy Gergely") -> 1050102 | E32: =GETPIVOTDATA("SzumElad",'KTGC-hez'!$C$4,"Kelt_hó",3,"Termékfajta","Beruházás","ÜK","Nagy Gergely") -> #REF! | F32: =GETPIVOTDATA("SzumElad",'KTGC-hez'!$C$4,"Kelt_hó",4,"Termékfajta","Beruházás","ÜK","Nagy Gergely") -> #REF! | G32: =GETPIVOTDATA("SzumElad",'KTGC-hez'!$C$4,"Kelt_hó",5,"Termékfajta","Beruházás","ÜK","Nagy Gergely") -> #REF! | H32: =GETPIVOTDATA("SzumElad",'KTGC-hez'!$C$4,"Kelt_hó",6,"Termékfajta","Beruházás","ÜK","Nagy Gergely") -> #REF! | I32: =GETPIVOTDATA("SzumElad",'KTGC-hez'!$C$4,"Kelt_hó",7,"Termékfajta","Beruházás","ÜK","Nagy Gergely") -> #REF! | J32: =GETPIVOTDATA("SzumElad",'KTGC-hez'!$C$4,"Kelt_hó",8,"Termékfajta","Beruházás","ÜK","Nagy Gergely") -> #REF! | K32: =GETPIVOTDATA("SzumElad",'KTGC-hez'!$C$4,"Kelt_hó",9,"Termékfajta","Beruházás","ÜK","Nagy Gergely") -> #REF! | L32: =GETPIVOTDATA("SzumElad",'KTGC-hez'!$C$4,"Kelt_hó",10,"Termékfajta","Beruházás","ÜK","Nagy Gergely") -> #REF! | M32: =GETPIVOTDATA("SzumElad",'KTGC-hez'!$C$4,"Kelt_hó",11,"Termékfajta","Beruházás","ÜK","Nagy Gergely") -> #REF! | N32: =GETPIVOTDATA("SzumElad",'KTGC-hez'!$C$4,"Kelt_hó",12,"Termékfajta","Beruházás","ÜK","Nagy Gergely") -> #REF! | O32: =SUM(C32:N32) -> #REF! | R32: Ha Alap > AlapLimit => KTGC = 360 000
A33: GNAGY | B33: Kumulált_ber | E33: =C32+D32+E32 -> #REF! | H33: =F32+G32+H32 -> #REF! | K33: =I32+J32+K32 -> #REF! | N33: =L32+M32+N32 -> #REF! | Q33: Bonusz: | R33: Ha Alap > BonuszLimit és ELAD > MinTerv
A34: GNAGY | B34: Kumulált_ber_terv | E34: =$U27*3 -> 10000000 | H34: =$U27*3 -> 10000000 | K34: =$U27*3 -> 10000000 | N34: =$U27*3 -> 10000000 | R34: Ha Elad > TERV => Bonusz = 120 000
A35: GNAGY | B35: BerBon | E35: =IF(E33>E34,180000,IF(E33>E34*0.9,100000,IF(E33>E34*0.75,60000,0))) -> #REF! | H35: =IF(H33>H34,180000,IF(H33>H34*0.9,100000,IF(H33>H34*0.75,60000,0))) -> #REF! | K35: =IF(K33>K34,180000,IF(K33>K34*0.9,100000,IF(K33>K34*0.75,60000,0))) -> #REF! | N35: =IF(N33>N34,180000,IF(N33>N34*0.9,100000,IF(N33>N34*0.75,60000,0))) -> #REF! | Q35: BerBon: | R35: Ha 3 havi Ber min. 75%os => 60 000
A36: GNAGY | B36: KTGC_26 | C36: =C28+C30+C35 -> 480000 | D36: =D28+D30+D35 -> 360394.83 | E36: =E28+E30+E35 -> #REF! | F36: =F28+F30+F35 -> #REF! | G36: =G28+G30+G35 -> #REF! | H36: =H28+H30+H35 -> #REF! | I36: =I28+I30+I35 -> #REF! | J36: =J28+J30+J35 -> #REF! | ... N36: =N28+N30+N35 -> #REF! | O36: =SUM(C36:N36) -> #REF! | R36: 90%-os => 100 000; 100%-os => 180 000
A37: GNAGY | B37: JUT_26 | C37: 17677 | D37: 169529 | O37: =SUM(C37:N37) -> 187206
B38: SZUM | C38: =SUM(C36:C37) -> 497677 | D38: =SUM(D36:D37) -> 529923.83 | E38: =SUM(E36:E37) -> #REF! | F38: =SUM(F36:F37) -> #REF! | G38: =SUM(G36:G37) -> #REF! | H38: =SUM(H36:H37) -> #REF! | I38: =SUM(I36:I37) -> #REF! | J38: =SUM(J36:J37) -> #REF! | ... O38: =SUM(O36:O37) -> #REF!
B39: JUT_25 | C39: 2347326 | D39: 134797
C40: =C39+C38 -> 2845003 | D40: =D39+D38 -> 664720.83 | E40: =E39+E38 -> #REF! | F40: =F39+F38 -> #REF! | G40: =G39+G38 -> #REF! | H40: =H39+H38 -> #REF! | I40: =I39+I38 -> #REF! | J40: =J39+J38 -> #REF! | ... N40: =N39+N38 -> #REF!
A43: UZL | B43: ÜK | C43: Jan | D43: Febr | E43: Márc | F43: Ápr | G43: Máj | H43: Jún | I43: Júl | J43: Aug | K43: Szept | L43: Okt | M43: Nov | N43: Dec | O43: SZUM | T43: Alap | U43: Ber
Q44: 2025 | R44: havi alapterv*0,9 | S44: havi alapterv
...

Sheet Külföld
A3: Sum of KÜlföldEUR | B3: Column Labels
A4: Row Labels | B4: 1 | C4: 2 | D4: Grand Total
A5: Dizalica doo | B5: 16696.5 | C5: 4596.99 | D5: 21293.49
A6: Gutman Lifting doo | C6: 14425.31 | D6: 14425.31
A7: Gutman Lifting s.r.o. | B7: 443.42 | C7: 2568.06 | D7: 3011.48
A8: Grand Total | B8: 17139.92 | C8: 21590.36 | D8: 38730.28

Sheet Beruházás
A1: Termékfajta | B1: Beruházás
B3: Column Labels
A5: Row Labels
A6: Grand Total

Sheet MB
A1: CSÉ | B1: 2026 | C1: Január | D1: Február | E1: Március | F1: Április | G1: Május | H1: Június | I1: Július | J1: Augusztus | K1: Szeptember | L1: Október | M1: November | N1: December | R1: CSÉ | S1: 2025 | T1: Január | U1: Február | V1: Március | W1: Április | X1: Május | Y1: Június | Z1: Július | AA1: Augusztus | AB1: Szeptember | AC1: Október | AD1: November | AE1: December
A2: Négyesy | C2: =GETPIVOTDATA("Árrés",'MB-hez Árrés'!$C$4,"Kelt_hó",1,"Termékfajta","Alap","ÜK","Négyesy Gábor") -> 3770941.3 | D2: =GETPIVOTDATA("Árrés",'MB-hez Árrés'!$C$4,"Kelt_hó",2,"Termékfajta","Alap","ÜK","Négyesy Gábor") -> 9933374.1 | O2: =SUM(C2:N2) -> 13704315 | R2: Négyesy | T2: 4531237.6 | U2: 8470404.4 | V2: 5540347.8 | W2: 7872961.5 | X2: 10802081 | Y2: 10322964 | Z2: 19865090 | AA2: 9553937.7 | AB2: 10181203 | AC2: 6157620.3 | AD2: 5358365.2 | AE2: 7507344.7 | AF2: 1.0616356e+08
A3: Nagy | C3: =GETPIVOTDATA("Árrés",'MB-hez Árrés'!$C$4,"Kelt_hó",1,"Termékfajta","Alap","ÜK","Nagy Gergely") -> 9647009.2 | D3: =GETPIVOTDATA("Árrés",'MB-hez Árrés'!$C$4,"Kelt_hó",2,"Termékfajta","Alap","ÜK","Nagy Gergely") -> 4403677.3 | O3: =SUM(C3:N3) -> 14050687 | R3: Nagy | T3: 3225367.5 | U3: 5608402.7 | V3: 3989751.7 | W3: 5733969.9 | X3: 7332786.7 | Y3: 4910665.7 | Z3: 17969519 | AA3: 18242357 | AB3: 12611371 | AC3: 10147168 | AD3: 18402636 | AE3: 5449658.3 | AF3: 1.1362365e+08
A4: H-ITB | C4: =GETPIVOTDATA("Árrés",'MB-hez Árrés'!$C$4,"Kelt_hó",1,"Termékfajta","Alap","ÜK","Forgó Tamás") -> 110088.93 | D4: =GETPIVOTDATA("Árrés",'MB-hez Árrés'!$C$4,"Kelt_hó",2,"Termékfajta","Alap","ÜK","Forgó Tamás") -> 8759768 | O4: =SUM(C4:N4) -> 8869856.9 | R4: H-ITB | T4: 5134997.8 | U4: 3366872 | V4: 7059072.3 | W4: 3509194 | X4: 313678.29 | Y4: 2805758.7 | Z4: 4253270.7 | AA4: 170537.28 | AB4: 4976579 | AC4: 7542071.9 | AD4: 3437084.6 | AE4: 4347534.1 | AF4: 46916651
C5: =SUM(C2:C4) -> 13528040 | D5: =SUM(D2:D4) -> 23096819 | E5: =SUM(E2:E4) -> 0 | F5: =SUM(F2:F4) -> 0 | G5: =SUM(G2:G4) -> 0 | H5: =SUM(H2:H4) -> 0 | I5: =SUM(I2:I4) -> 0 | J5: =SUM(J2:J4) -> 0 | ... N5: =SUM(N2:N4) -> 0 | O5: =SUM(C5:N5) -> 36624859 | T5: 12891603 | U5: 17445679 | V5: 16589172 | W5: 17116125 | X5: 18448546 | Y5: 18039389 | Z5: 42087879 | AA5: 27966832 | AB5: 27769152 | AC5: 23846860 | AD5: 27198086 | AE5: 17304537 | AF5: 2.6670386e+08
A6: 10000000 | B6: 200000 | C6: =IF(C$5>$A6,$B6,0) -> 200000 | D6: =IF(D$5>$A6,$B6,0) -> 200000 | E6: =IF(E$5>$A6,$B6,0) -> 0 | F6: =IF(F$5>$A6,$B6,0) -> 0 | G6: =IF(G$5>$A6,$B6,0) -> 0 | H6: =IF(H$5>$A6,$B6,0) -> 0 | I6: =IF(I$5>$A6,$B6,0) -> 0 | J6: =IF(J$5>$A6,$B6,0) -> 0 | ... N6: =IF(N$5>$A6,$B6,0) -> 0 | O6: =SUM(C6:N6) -> 400000 | R6: 10000000 | S6: 200000 | T6: 200000 | U6: 200000 | V6: 200000 | W6: 200000 | X6: 200000 | Y6: 200000 | Z6: 200000 | AA6: 200000 | AB6: 200000 | AC6: 200000 | AD6: 200000 | AE6: 200000 | AF6: 2400000
A7: 13000000 | B7: 50000 | C7: =IF(C$5>$A7,$B7,0) -> 50000 | D7: =IF(D$5>$A7,$B7,0) -> 50000 | E7: =IF(E$5>$A7,$B7,0) -> 0 | F7: =IF(F$5>$A7,$B7,0) -> 0 | G7: =IF(G$5>$A7,$B7,0) -> 0 | H7: =IF(H$5>$A7,$B7,0) -> 0 | I7: =IF(I$5>$A7,$B7,0) -> 0 | J7: =IF(J$5>$A7,$B7,0) -> 0 | ... N7: =IF(N$5>$A7,$B7,0) -> 0 | O7: =SUM(C7:N7) -> 100000 | R7: 13000000 | S7: 50000 | T7: 0 | U7: 50000 | V7: 50000 | W7: 50000 | X7: 50000 | Y7: 50000 | Z7: 50000 | AA7: 50000 | AB7: 50000 | AC7: 50000 | AD7: 50000 | AE7: 50000 | AF7: 550000
A8: 16000000 | B8: 50000 | C8: =IF(C$5>$A8,$B8,0) -> 0 | D8: =IF(D$5>$A8,$B8,0) -> 50000 | E8: =IF(E$5>$A8,$B8,0) -> 0 | F8: =IF(F$5>$A8,$B8,0) -> 0 | G8: =IF(G$5>$A8,$B8,0) -> 0 | H8: =IF(H$5>$A8,$B8,0) -> 0 | I8: =IF(I$5>$A8,$B8,0) -> 0 | J8: =IF(J$5>$A8,$B8,0) -> 0 | ... N8: =IF(N$5>$A8,$B8,0) -> 0 | O8: =SUM(C8:N8) -> 50000 | R8: 16000000 | S8: 50000 | T8: 0 | U8: 50000 | V8: 50000 | W8: 50000 | X8: 50000 | Y8: 50000 | Z8: 50000 | AA8: 50000 | AB8: 50000 | AC8: 50000 | AD8: 50000 | AE8: 50000 | AF8: 550000
A9: 19000000 | B9: 50000 | C9: =IF(C$5>$A9,$B9,0) -> 0 | D9: =IF(D$5>$A9,$B9,0) -> 50000 | E9: =IF(E$5>$A9,$B9,0) -> 0 | F9: =IF(F$5>$A9,$B9,0) -> 0 | G9: =IF(G$5>$A9,$B9,0) -> 0 | H9: =IF(H$5>$A9,$B9,0) -> 0 | I9: =IF(I$5>$A9,$B9,0) -> 0 | J9: =IF(J$5>$A9,$B9,0) -> 0 | ... N9: =IF(N$5>$A9,$B9,0) -> 0 | O9: =SUM(C9:N9) -> 50000 | R9: 19000000 | S9: 50000 | T9: 0 | U9: 0 | V9: 0 | W9: 0 | X9: 0 | Y9: 0 | Z9: 50000 | AA9: 50000 | AB9: 50000 | AC9: 50000 | AD9: 50000 | AE9: 0 | AF9: 250000
A10: 22000000 | B10: 50000 | C10: =IF(C$5>$A10,$B10,0) -> 0 | D10: =IF(D$5>$A10,$B10,0) -> 50000 | E10: =IF(E$5>$A10,$B10,0) -> 0 | F10: =IF(F$5>$A10,$B10,0) -> 0 | G10: =IF(G$5>$A10,$B10,0) -> 0 | H10: =IF(H$5>$A10,$B10,0) -> 0 | I10: =IF(I$5>$A10,$B10,0) -> 0 | J10: =IF(J$5>$A10,$B10,0) -> 0 | ... N10: =IF(N$5>$A10,$B10,0) -> 0 | O10: =SUM(C10:N10) -> 50000 | R10: 22000000 | S10: 50000 | T10: 0 | U10: 0 | V10: 0 | W10: 0 | X10: 0 | Y10: 0 | Z10: 50000 | AA10: 50000 | AB10: 50000 | AC10: 50000 | AD10: 50000 | AE10: 0 | AF10: 250000
A11: 24000000 | B11: 50000 | C11: =IF(C$5>$A11,$B11,0) -> 0 | D11: =IF(D$5>$A11,$B11,0) -> 0 | E11: =IF(E$5>$A11,$B11,0) -> 0 | F11: =IF(F$5>$A11,$B11,0) -> 0 | G11: =IF(G$5>$A11,$B11,0) -> 0 | H11: =IF(H$5>$A11,$B11,0) -> 0 | I11: =IF(I$5>$A11,$B11,0) -> 0 | J11: =IF(J$5>$A11,$B11,0) -> 0 | ... N11: =IF(N$5>$A11,$B11,0) -> 0
B12: 2026 | C12: =SUM(C6:C11) -> 250000 | D12: =SUM(D6:D11) -> 400000 | E12: =SUM(E6:E11) -> 0 | F12: =SUM(F6:F11) -> 0 | G12: =SUM(G6:G11) -> 0 | H12: =SUM(H6:H11) -> 0 | I12: =SUM(I6:I11) -> 0 | J12: =SUM(J6:J11) -> 0 | ... N12: =SUM(N6:N11) -> 0 | O12: =SUM(C12:N12) -> 650000 | P12: =O12/12 -> 54166.667 | R12: 2025 | S12: 2025 | T12: 200000 | U12: 300000 | V12: 300000 | W12: 300000 | X12: 300000 | Y12: 300000 | Z12: 400000 | AA12: 400000 | AB12: 400000 | AC12: 400000 | AD12: 400000 | AE12: 300000 | AF12: 4000000 | AG12: 333333.33
B13: 2026 | C13: 950000 | D13: 1050000 | E13: 1050000 | F13: 1050000 | G13: 1050000 | H13: 1050000 | I13: 1050000 | J13: 1050000 | K13: 1050000 | L13: 1050000 | M13: 1050000 | N13: 1050000 | O13: =SUM(C13:N13) -> 12500000 | R13: 2025 | S13: 2025 | T13: 870000 | U13: 870000 | V13: 870000 | W13: 870000 | X13: 870000 | Y13: 870000 | Z13: 950000 | AA13: 950000 | AB13: 950000 | AC13: 950000 | AD13: 950000 | AE13: 950000 | AF13: 10920000 | AG13: 910000
